Workbook

Sheet Guide
A1: Edition des rencontres
A2: Utilise la feuille Encounters. Saisis pokemon_id, poids, niveaux et method_1/2/3. Les noms et methods se remplissent automatiquement.
A3: Ensuite exporte vers le CSV runtime avec: npm run zone:editor:export

Sheet Lists
A1: zone_type | B1: combat_enabled | C1: encounter_method
A2: route | B2: true | C2: walk
A3: city | B3: false | C3: surf
A4: dungeon | C4: old-rod
C5: good-rod
C6: super-rod
C7: gift
C8: only-one
C9: pokeflute
C10: rock-smash

Sheet PokemonRef
A1: pokemon_id | B1: pokemon_name_en | C1: pokemon_name_fr
A2: 1 | B2: bulbasaur | C2: Bulbizarre
A3: 2 | B3: ivysaur | C3: Herbizarre
A4: 3 | B4: venusaur | C4: Florizarre
A5: 4 | B5: charmander | C5: Salamèche
A6: 5 | B6: charmeleon | C6: Reptincel
A7: 6 | B7: charizard | C7: Dracaufeu
A8: 7 | B8: squirtle | C8: Carapuce
A9: 8 | B9: wartortle | C9: Carabaffe
A10: 9 | B10: blastoise | C10: Tortank
A11: 10 | B11: caterpie | C11: Chenipan
A12: 11 | B12: metapod | C12: Chrysacier
A13: 12 | B13: butterfree | C13: Papilusion
... A494: 493 | B494: arceus | C494: Arceus

Sheet Encounters
A1: route_id | B1: route_name_fr | C1: zone_type | D1: combat_enabled | E1: pokemon_id | F1: pokemon_name_fr | G1: pokemon_name_en | H1: spawn_weight | I1: min_level | J1: max_level | K1: method_1 | L1: method_2 | M1: method_3 | N1: methods | O1: notes
A2: kanto_city_pallet_town | B2: Bourg Palette (Kanto) | C2: town | D2: false
A3: kanto_route_1 | B3: Route 1 (Kanto) | C3: route | D3: true | E3: 16 | F3: =IF($E3="","",IFERROR(INDEX(PokemonRef!$C$2:$C$494,MATCH($E3,PokemonRef!$A$2:$A$494,0)),"")) | G3: =IF($E3="","",IFERROR(INDEX(PokemonRef!$B$2:$B$494,MATCH($E3,PokemonRef!$A$2:$A$494,0)),"")) | H3: 50 | I3: 2 | J3: 5 | K3: walk | N3: =IF($E3="","",TEXTJOIN("|",TRUE,K3:M3))
A4: kanto_route_1 | B4: Route 1 (Kanto) | C4: route | D4: true | E4: 19 | F4: =IF($E4="","",IFERROR(INDEX(PokemonRef!$C$2:$C$494,MATCH($E4,PokemonRef!$A$2:$A$494,0)),"")) | G4: =IF($E4="","",IFERROR(INDEX(PokemonRef!$B$2:$B$494,MATCH($E4,PokemonRef!$A$2:$A$494,0)),"")) | H4: 50 | I4: 2 | J4: 4 | K4: walk | N4: =IF($E4="","",TEXTJOIN("|",TRUE,K4:M4))
A5: kanto_city_viridian_city | B5: Jadielle (Kanto) | C5: town | D5: false
A6: kanto_route_2 | B6: Route 2 (Kanto) | C6: route | D6: true | E6: 16 | F6: =IF($E6="","",IFERROR(INDEX(PokemonRef!$C$2:$C$494,MATCH($E6,PokemonRef!$A$2:$A$494,0)),"")) | G6: =IF($E6="","",IFERROR(INDEX(PokemonRef!$B$2:$B$494,MATCH($E6,PokemonRef!$A$2:$A$494,0)),"")) | H6: 45 | I6: 2 | J6: 5 | K6: walk | N6: =IF($E6="","",TEXTJOIN("|",TRUE,K6:M6))
A7: kanto_route_2 | B7: Route 2 (Kanto) | C7: route | D7: true | E7: 19 | F7: =IF($E7="","",IFERROR(INDEX(PokemonRef!$C$2:$C$494,MATCH($E7,PokemonRef!$A$2:$A$494,0)),"")) | G7: =IF($E7="","",IFERROR(INDEX(PokemonRef!$B$2:$B$494,MATCH($E7,PokemonRef!$A$2:$A$494,0)),"")) | H7: 45 | I7: 2 | J7: 5 | K7: walk | N7: =IF($E7="","",TEXTJOIN("|",TRUE,K7:M7))
A8: kanto_route_2 | B8: Route 2 (Kanto) | C8: route | D8: true | E8: 10 | F8: =IF($E8="","",IFERROR(INDEX(PokemonRef!$C$2:$C$494,MATCH($E8,PokemonRef!$A$2:$A$494,0)),"")) | G8: =IF($E8="","",IFERROR(INDEX(PokemonRef!$B$2:$B$494,MATCH($E8,PokemonRef!$A$2:$A$494,0)),"")) | H8: 5 | I8: 4 | J8: 5 | K8: walk | N8: =IF($E8="","",TEXTJOIN("|",TRUE,K8:M8))
A9: kanto_route_2 | B9: Route 2 (Kanto) | C9: route | D9: true | E9: 13 | F9: =IF($E9="","",IFERROR(INDEX(PokemonRef!$C$2:$C$494,MATCH($E9,PokemonRef!$A$2:$A$494,0)),"")) | G9: =IF($E9="","",IFERROR(INDEX(PokemonRef!$B$2:$B$494,MATCH($E9,PokemonRef!$A$2:$A$494,0)),"")) | H9: 5 | I9: 4 | J9: 5 | K9: walk | N9: =IF($E9="","",TEXTJOIN("|",TRUE,K9:M9))
A10: kanto_dungeon_viridian_forest | B10: Foret de Jade (Kanto) | C10: dungeon | D10: true | E10: 10 | F10: =IF($E10="","",IFERROR(INDEX(PokemonRef!$C$2:$C$494,MATCH($E10,PokemonRef!$A$2:$A$494,0)),"")) | G10: =IF($E10="","",IFERROR(INDEX(PokemonRef!$B$2:$B$494,MATCH($E10,PokemonRef!$A$2:$A$494,0)),"")) | H10: 40 | I10: 3 | J10: 5 | K10: walk | N10: =IF($E10="","",TEXTJOIN("|",TRUE,K10:M10))
A11: kanto_dungeon_viridian_forest | B11: Foret de Jade (Kanto) | C11: dungeon | D11: true | E11: 13 | F11: =IF($E11="","",IFERROR(INDEX(PokemonRef!$C$2:$C$494,MATCH($E11,PokemonRef!$A$2:$A$494,0)),"")) | G11: =IF($E11="","",IFERROR(INDEX(PokemonRef!$B$2:$B$494,MATCH($E11,PokemonRef!$A$2:$A$494,0)),"")) | H11: 40 | I11: 3 | J11: 5 | K11: walk | N11: =IF($E11="","",TEXTJOIN("|",TRUE,K11:M11))
A12: kanto_dungeon_viridian_forest | B12: Foret de Jade (Kanto) | C12: dungeon | D12: true | E12: 11 | F12: =IF($E12="","",IFERROR(INDEX(PokemonRef!$C$2:$C$494,MATCH($E12,PokemonRef!$A$2:$A$494,0)),"")) | G12: =IF($E12="","",IFERROR(INDEX(PokemonRef!$B$2:$B$494,MATCH($E12,PokemonRef!$A$2:$A$494,0)),"")) | H12: 10 | I12: 4 | J12: 6 | K12: walk | N12: =IF($E12="","",TEXTJOIN("|",TRUE,K12:M12))
A13: kanto_dungeon_viridian_forest | B13: Foret de Jade (Kanto) | C13: dungeon | D13: true | E13: 14 | F13: =IF($E13="","",IFERROR(INDEX(PokemonRef!$C$2:$C$494,MATCH($E13,PokemonRef!$A$2:$A$494,0)),"")) | G13: =IF($E13="","",IFERROR(INDEX(PokemonRef!$B$2:$B$494,MATCH($E13,PokemonRef!$A$2:$A$494,0)),"")) | H13: 10 | I13: 4 | J13: 6 | K13: walk | N13: =IF($E13="","",TEXTJOIN("|",TRUE,K13:M13))
A14: kanto_dungeon_viridian_forest | B14: Foret de Jade (Kanto) | C14: dungeon | D14: true | E14: 25 | F14: =IF($E14="","",IFERROR(INDEX(PokemonRef!$C$2:$C$494,MATCH($E14,PokemonRef!$A$2:$A$494,0)),"")) | G14: =IF($E14="","",IFERROR(INDEX(PokemonRef!$B$2:$B$494,MATCH($E14,PokemonRef!$A$2:$A$494,0)),"")) | H14: 5 | I14: 3 | J14: 5 | K14: walk | N14: =IF($E14="","",TEXTJOIN("|",TRUE,K14:M14))
A15: kanto_city_pewter_city | B15: Argenta (Kanto) | C15: town | D15: false
A16: kanto_route_3 | B16: Route 3 (Kanto) | C16: route | D16: true | E16: 129 | F16: =IF($E16="","",IFERROR(INDEX(PokemonRef!$C$2:$C$494,MATCH($E16,PokemonRef!$A$2:$A$494,0)),"")) | G16: =IF($E16="","",IFERROR(INDEX(PokemonRef!$B$2:$B$494,MATCH($E16,PokemonRef!$A$2:$A$494,0)),"")) | H16: 100 | I16: 5 | J16: 5 | K16: gift | N16: =IF($E16="","",TEXTJOIN("|",TRUE,K16:M16))
A17: kanto_route_3 | B17: Route 3 (Kanto) | C17: route | D17: true | E17: 21 | F17: =IF($E17="","",IFERROR(INDEX(PokemonRef!$C$2:$C$494,MATCH($E17,PokemonRef!$A$2:$A$494,0)),"")) | G17: =IF($E17="","",IFERROR(INDEX(PokemonRef!$B$2:$B$494,MATCH($E17,PokemonRef!$A$2:$A$494,0)),"")) | H17: 35 | I17: 6 | J17: 8 | K17: walk | N17: =IF($E17="","",TEXTJOIN("|",TRUE,K17:M17))
A18: kanto_route_3 | B18: Route 3 (Kanto) | C18: route | D18: true | E18: 16 | F18: =IF($E18="","",IFERROR(INDEX(PokemonRef!$C$2:$C$494,MATCH($E18,PokemonRef!$A$2:$A$494,0)),"")) | G18: =IF($E18="","",IFERROR(INDEX(PokemonRef!$B$2:$B$494,MATCH($E18,PokemonRef!$A$2:$A$494,0)),"")) | H18: 30 | I18: 6 | J18: 7 | K18: walk | N18: =IF($E18="","",TEXTJOIN("|",TRUE,K18:M18))
A19: kanto_route_3 | B19: Route 3 (Kanto) | C19: route | D19: true | E19: 29 | F19: =IF($E19="","",IFERROR(INDEX(PokemonRef!$C$2:$C$494,MATCH($E19,PokemonRef!$A$2:$A$494,0)),"")) | G19: =IF($E19="","",IFERROR(INDEX(PokemonRef!$B$2:$B$494,MATCH($E19,PokemonRef!$A$2:$A$494,0)),"")) | H19: 14 | I19: 6 | J19: 7 | K19: walk | N19: =IF($E19="","",TEXTJOIN("|",TRUE,K19:M19))
A20: kanto_route_3 | B20: Route 3 (Kanto) | C20: route | D20: true | E20: 32 | F20: =IF($E20="","",IFERROR(INDEX(PokemonRef!$C$2:$C$494,MATCH($E20,PokemonRef!$A$2:$A$494,0)),"")) | G20: =IF($E20="","",IFERROR(INDEX(PokemonRef!$B$2:$B$494,MATCH($E20,PokemonRef!$A$2:$A$494,0)),"")) | H20: 14 | I20: 6 | J20: 7 | K20: walk | N20: =IF($E20="","",TEXTJOIN("|",TRUE,K20:M20))
A21: kanto_route_3 | B21: Route 3 (Kanto) | C21: route | D21: true | E21: 39 | F21: =IF($E21="","",IFERROR(INDEX(PokemonRef!$C$2:$C$494,MATCH($E21,PokemonRef!$A$2:$A$494,0)),"")) | G21: =IF($E21="","",IFERROR(INDEX(PokemonRef!$B$2:$B$494,MATCH($E21,PokemonRef!$A$2:$A$494,0)),"")) | H21: 10 | I21: 3 | J21: 7 | K21: walk | N21: =IF($E21="","",TEXTJOIN("|",TRUE,K21:M21))
A22: kanto_route_3 | B22: Route 3 (Kanto) | C22: route | D22: true | E22: 56 | F22: =IF($E22="","",IFERROR(INDEX(PokemonRef!$C$2:$C$494,MATCH($E22,PokemonRef!$A$2:$A$494,0)),"")) | G22: =IF($E22="","",IFERROR(INDEX(PokemonRef!$B$2:$B$494,MATCH($E22,PokemonRef!$A$2:$A$494,0)),"")) | H22: 10 | I22: 7 | J22: 7 | K22: walk | N22: =IF($E22="","",TEXTJOIN("|",TRUE,K22:M22))
A23: kanto_dungeon_mt_moon | B23: Mont Selenite (Kanto) | C23: dungeon | D23: true | E23: 46 | F23: =IF($E23="","",IFERROR(INDEX(PokemonRef!$C$2:$C$494,MATCH($E23,PokemonRef!$A$2:$A$494,0)),"")) | G23: =IF($E23="","",IFERROR(INDEX(PokemonRef!$B$2:$B$494,MATCH($E23,PokemonRef!$A$2:$A$494,0)),"")) | H23: 100 | I23: 5 | J23: 12 | K23: walk | N23: =IF($E23="","",TEXTJOIN("|",TRUE,K23:M23))
A24: kanto_dungeon_mt_moon | B24: Mont Selenite (Kanto) | C24: dungeon | D24: true | E24: 41 | F24: =IF($E24="","",IFERROR(INDEX(PokemonRef!$C$2:$C$494,MATCH($E24,PokemonRef!$A$2:$A$494,0)),"")) | G24: =IF($E24="","",IFERROR(INDEX(PokemonRef!$B$2:$B$494,MATCH($E24,PokemonRef!$A$2:$A$494,0)),"")) | H24: 69 | I24: 7 | J24: 11 | K24: walk | N24: =IF($E24="","",TEXTJOIN("|",TRUE,K24:M24))
A25: kanto_dungeon_mt_moon | B25: Mont Selenite (Kanto) | C25: dungeon | D25: true | E25: 74 | F25: =IF($E25="","",IFERROR(INDEX(PokemonRef!$C$2:$C$494,MATCH($E25,PokemonRef!$A$2:$A$494,0)),"")) | G25: =IF($E25="","",IFERROR(INDEX(PokemonRef!$B$2:$B$494,MATCH($E25,PokemonRef!$A$2:$A$494,0)),"")) | H25: 30 | I25: 7 | J25: 10 | K25: walk | N25: =IF($E25="","",TEXTJOIN("|",TRUE,K25:M25))
A26: kanto_dungeon_mt_moon | B26: Mont Selenite (Kanto) | C26: dungeon | D26: true | E26: 35 | F26: =IF($E26="","",IFERROR(INDEX(PokemonRef!$C$2:$C$494,MATCH($E26,PokemonRef!$A$2:$A$494,0)),"")) | G26: =IF($E26="","",IFERROR(INDEX(PokemonRef!$B$2:$B$494,MATCH($E26,PokemonRef!$A$2:$A$494,0)),"")) | H26: 6 | I26: 8 | J26: 12 | K26: walk | N26: =IF($E26="","",TEXTJOIN("|",TRUE,K26:M26))
A27: kanto_route_4 | B27: Route 4 (Kanto) | C27: route | D27: true | E27: 98 | F27: =IF($E27="","",IFERROR(INDEX(PokemonRef!$C$2:$C$494,MATCH($E27,PokemonRef!$A$2:$A$494,0)),"")) | G27: =IF($E27="","",IFERROR(INDEX(PokemonRef!$B$2:$B$494,MATCH($E27,PokemonRef!$A$2:$A$494,0)),"")) | H27: 144 | I27: 5 | J27: 35 | K27: good-rod | L27: super-rod | N27: =IF($E27="","",TEXTJOIN("|",TRUE,K27:M27))
A28: kanto_route_4 | B28: Route 4 (Kanto) | C28: route | D28: true | E28: 116 | F28: =IF($E28="","",IFERROR(INDEX(PokemonRef!$C$2:$C$494,MATCH($E28,PokemonRef!$A$2:$A$494,0)),"")) | G28: =IF($E28="","",IFERROR(INDEX(PokemonRef!$B$2:$B$494,MATCH($E28,PokemonRef!$A$2:$A$494,0)),"")) | H28: 144 | I28: 5 | J28: 35 | K28: good-rod | L28: super-rod | N28: =IF($E28="","",TEXTJOIN("|",TRUE,K28:M28))
A29: kanto_route_4 | B29: Route 4 (Kanto) | C29: route | D29: true | E29: 129 | F29: =IF($E29="","",IFERROR(INDEX(PokemonRef!$C$2:$C$494,MATCH($E29,PokemonRef!$A$2:$A$494,0)),"")) | G29: =IF($E29="","",IFERROR(INDEX(PokemonRef!$B$2:$B$494,MATCH($E29,PokemonRef!$A$2:$A$494,0)),"")) | H29: 120 | I29: 5 | J29: 15 | K29: gift | L29: good-rod | M29: old-rod | N29: =IF($E29="","",TEXTJOIN("|",TRUE,K29:M29))
A30: kanto_route_4 | B30: Route 4 (Kanto) | C30: route | D30: true | E30: 72 | F30: =IF($E30="","",IFERROR(INDEX(PokemonRef!$C$2:$C$494,MATCH($E30,PokemonRef!$A$2:$A$494,0)),"")) | G30: =IF($E30="","",IFERROR(INDEX(PokemonRef!$B$2:$B$494,MATCH($E30,PokemonRef!$A$2:$A$494,0)),"")) | H30: 100 | I30: 5 | J30: 40 | K30: surf | N30: =IF($E30="","",TEXTJOIN("|",TRUE,K30:M30))
A31: kanto_route_4 | B31: Route 4 (Kanto) | C31: route | D31: true | E31: 19 | F31: =IF($E31="","",IFERROR(INDEX(PokemonRef!$C$2:$C$494,MATCH($E31,PokemonRef!$A$2:$A$494,0)),"")) | G31: =IF($E31="","",IFERROR(INDEX(PokemonRef!$B$2:$B$494,MATCH($E31,PokemonRef!$A$2:$A$494,0)),"")) | H31: 35 | I31: 8 | J31: 12 | K31: walk | N31: =IF($E31="","",TEXTJOIN("|",TRUE,K31:M31))
A32: kanto_route_4 | B32: Route 4 (Kanto) | C32: route | D32: true | E32: 21 | F32: =IF($E32="","",IFERROR(INDEX(PokemonRef!$C$2:$C$494,MATCH($E32,PokemonRef!$A$2:$A$494,0)),"")) | G32: =IF($E32="","",IFERROR(INDEX(PokemonRef!$B$2:$B$494,MATCH($E32,PokemonRef!$A$2:$A$494,0)),"")) | H32: 35 | I32: 8 | J32: 12 | K32: walk | N32: =IF($E32="","",TEXTJOIN("|",TRUE,K32:M32))
A33: kanto_route_4 | B33: Route 4 (Kanto) | C33: route | D33: true | E33: 23 | F33: =IF($E33="","",IFERROR(INDEX(PokemonRef!$C$2:$C$494,MATCH($E33,PokemonRef!$A$2:$A$494,0)),"")) | G33: =IF($E33="","",IFERROR(INDEX(PokemonRef!$B$2:$B$494,MATCH($E33,PokemonRef!$A$2:$A$494,0)),"")) | H33: 25 | I33: 6 | J33: 12 | K33: walk | N33: =IF($E33="","",TEXTJOIN("|",TRUE,K33:M33))
A34: kanto_route_4 | B34: Route 4 (Kanto) | C34: route | D34: true | E34: 27 | F34: =IF($E34="","",IFERROR(INDEX(PokemonRef!$C$2:$C$494,MATCH($E34,PokemonRef!$A$2:$A$494,0)),"")) | G34: =IF($E34="","",IFERROR(INDEX(PokemonRef!$B$2:$B$494,MATCH($E34,PokemonRef!$A$2:$A$494,0)),"")) | H34: 25 | I34: 6 | J34: 12 | K34: walk | N34: =IF($E34="","",TEXTJOIN("|",TRUE,K34:M34))
A35: kanto_route_4 | B35: Route 4 (Kanto) | C35: route | D35: true | E35: 130 | F35: =IF($E35="","",IFERROR(INDEX(PokemonRef!$C$2:$C$494,MATCH($E35,PokemonRef!$A$2:$A$494,0)),"")) | G35: =IF($E35="","",IFERROR(INDEX(PokemonRef!$B$2:$B$494,MATCH($E35,PokemonRef!$A$2:$A$494,0)),"")) | H35: 15 | I35: 15 | J35: 25 | K35: super-rod | N35: =IF($E35="","",TEXTJOIN("|",TRUE,K35:M35))
A36: kanto_route_4 | B36: Route 4 (Kanto) | C36: route | D36: true | E36: 56 | F36: =IF($E36="","",IFERROR(INDEX(PokemonRef!$C$2:$C$494,MATCH($E36,PokemonRef!$A$2:$A$494,0)),"")) | G36: =IF($E36="","",IFERROR(INDEX(PokemonRef!$B$2:$B$494,MATCH($E36,PokemonRef!$A$2:$A$494,0)),"")) | H36: 5 | I36: 10 | J36: 12 | K36: walk | N36: =IF($E36="","",TEXTJOIN("|",TRUE,K36:M36))
A37: kanto_route_4 | B37: Route 4 (Kanto) | C37: route | D37: true | E37: 54 | F37: =IF($E37="","",IFERROR(INDEX(PokemonRef!$C$2:$C$494,MATCH($E37,PokemonRef!$A$2:$A$494,0)),"")) | G37: =IF($E37="","",IFERROR(INDEX(PokemonRef!$B$2:$B$494,MATCH($E37,PokemonRef!$A$2:$A$494,0)),"")) | H37: 1 | I37: 25 | J37: 35 | K37: super-rod | N37: =IF($E37="","",TEXTJOIN("|",TRUE,K37:M37))
A38: kanto_route_4 | B38: Route 4 (Kanto) | C38: route | D38: true | E38: 79 | F38: =IF($E38="","",IFERROR(INDEX(PokemonRef!$C$2:$C$494,MATCH($E38,PokemonRef!$A$2:$A$494,0)),"")) | G38: =IF($E38="","",IFERROR(INDEX(PokemonRef!$B$2:$B$494,MATCH($E38,PokemonRef!$A$2:$A$494,0)),"")) | H38: 1 | I38: 25 | J38: 35 | K38: super-rod | N38: =IF($E38="","",TEXTJOIN("|",TRUE,K38:M38))
A39: kanto_city_cerulean_city | B39: Azuria (Kanto) | C39: town | D39: false
A40: kanto_route_24 | B40: Route 24 (Kanto) | C40: route | D40: true | E40: 98 | F40: =IF($E40="","",IFERROR(INDEX(PokemonRef!$C$2:$C$494,MATCH($E40,PokemonRef!$A$2:$A$494,0)),"")) | G40: =IF($E40="","",IFERROR(INDEX(PokemonRef!$B$2:$B$494,MATCH($E40,PokemonRef!$A$2:$A$494,0)),"")) | H40: 144 | I40: 5 | J40: 35 | K40: good-rod | L40: super-rod | N40: =IF($E40="","",TEXTJOIN("|",TRUE,K40:M40))
...
